Workbook

Sheet Instructions
A1: Feedback Kitchen v.2.0 — Instructions
A2: Welcome to the MRKTG101 Feedback Kitchen.
A3: This tool is designed to speed up marking, reduce errors, and standardise feedback while still allowing tutor judgement and personalisation.
A4: Follow the steps below when completing a student’s assessment.
A6: 1. Enter Student Details
A7: Fill in the yellow cells at the top of the orange Kitchen Tab:
A8: • Student Name
A9: • Student ID
A10: • Tutor
A11: • Date (autopopulated)
A12: These fields are recommended for record‑keeping and to assist with any review related to student queries etc.
A14: 2. Select a Grade for Each Criterion
... A60: Adapted from the Feedback Kitchen tool originally developed and kindly shared by Dr. Michael Harker, University of Strathclyde. Redesigned for MRKTG101 at the University of Waikato to reflect the 5Cs analysis framework and UW grading policy. Developed with AI assistance (Claude, Anthropic & MS Copilot).

Sheet Kitchen
A1: FEEDBACK KITCHEN | MRKTG101 – 5Cs Analysis | University of Waikato
A2: Progress Report 1 | Weighting: 15% of final grade | v2.0
A4: Student Name: | C4: Student ID: | E4: Tutor: | G4: Date:
B5: Mickey Mouse | D5: 1647841 | F5: SM | H5: =TODAY() -> 46087
A7: Criterion | B7: Weight (%) | C7: Grade (select ▼) | D7: Midpoint Score | E7: Override Score | F7: Final Score | G7: Tier No. | H7: Feedback Tier
A8: New Product Idea | B8: 15 | C8: C- | D8: =IF(C8="","",VLOOKUP(C8,Ingredients!$A$12:$B$21,2,FALSE())) -> 52 | F8: =IF(E8<>"",E8,IF(D8="","",D8)) -> 52 | G8: =IF(C8="","",VLOOKUP(C8,Ingredients!$A$25:$C$34,3,FALSE())) -> 2 | H8: =IF(C8="","",VLOOKUP(C8,Ingredients!$A$25:$C$34,2,FALSE())) -> Developing
A9: Context – PESTLE | B9: 20 | C9: B | D9: =IF(C9="","",VLOOKUP(C9,Ingredients!$A$12:$B$21,2,FALSE())) -> 72 | E9: 71 | F9: =IF(E9<>"",E9,IF(D9="","",D9)) -> 71 | G9: =IF(C9="","",VLOOKUP(C9,Ingredients!$A$25:$C$34,3,FALSE())) -> 3 | H9: =IF(C9="","",VLOOKUP(C9,Ingredients!$A$25:$C$34,2,FALSE())) -> Proficient
A10: Company – SWOT | B10: 20 | C10: B- | D10: =IF(C10="","",VLOOKUP(C10,Ingredients!$A$12:$B$21,2,FALSE())) -> 67 | F10: =IF(E10<>"",E10,IF(D10="","",D10)) -> 67 | G10: =IF(C10="","",VLOOKUP(C10,Ingredients!$A$25:$C$34,3,FALSE())) -> 3 | H10: =IF(C10="","",VLOOKUP(C10,Ingredients!$A$25:$C$34,2,FALSE())) -> Proficient
A11: Competition | B11: 15 | C11: C | D11: =IF(C11="","",VLOOKUP(C11,Ingredients!$A$12:$B$21,2,FALSE())) -> 57 | F11: =IF(E11<>"",E11,IF(D11="","",D11)) -> 57 | G11: =IF(C11="","",VLOOKUP(C11,Ingredients!$A$25:$C$34,3,FALSE())) -> 2 | H11: =IF(C11="","",VLOOKUP(C11,Ingredients!$A$25:$C$34,2,FALSE())) -> Developing
A12: Collaborators | B12: 10 | C12: D | D12: =IF(C12="","",VLOOKUP(C12,Ingredients!$A$12:$B$21,2,FALSE())) -> 44 | F12: =IF(E12<>"",E12,IF(D12="","",D12)) -> 44 | G12: =IF(C12="","",VLOOKUP(C12,Ingredients!$A$25:$C$34,3,FALSE())) -> 1 | H12: =IF(C12="","",VLOOKUP(C12,Ingredients!$A$25:$C$34,2,FALSE())) -> Unsatisfactory
A13: Customers | B13: 10 | C13: C | D13: =IF(C13="","",VLOOKUP(C13,Ingredients!$A$12:$B$21,2,FALSE())) -> 57 | F13: =IF(E13<>"",E13,IF(D13="","",D13)) -> 57 | G13: =IF(C13="","",VLOOKUP(C13,Ingredients!$A$25:$C$34,3,FALSE())) -> 2 | H13: =IF(C13="","",VLOOKUP(C13,Ingredients!$A$25:$C$34,2,FALSE())) -> Developing
A14: Writing & Presentation (incl. APA 7th) | B14: 10 | C14: C | D14: =IF(C14="","",VLOOKUP(C14,Ingredients!$A$12:$B$21,2,FALSE())) -> 57 | F14: =IF(E14<>"",E14,IF(D14="","",D14)) -> 57 | G14: =IF(C14="","",VLOOKUP(C14,Ingredients!$A$25:$C$34,3,FALSE())) -> 2 | H14: =IF(C14="","",VLOOKUP(C14,Ingredients!$A$25:$C$34,2,FALSE())) -> Developing
A16: Weighting check (must total 100): | F16: =SUM(B8:B14) -> 100 | G16: =IF(SUM(B8:B14)=100,"✓ OK","⚠ Weights must total 100 — score invalid") -> ✓ OK
A18: Weighted Score /100: | F18: =IF(SUM(B8:B14)<>100,"⚠",IF(COUNTA(C8:C14)=0,"",ROUND(SUMPRODUCT(F8:F14,B8:B14)/100,1))) -> 59.8
A19: Late Submission Penalty: | D19: 2 days late | F19: =IF(OR(D19="",D19="On time"),0,IF(D19="1 day late",10,IF(D19="2 days late",20,30))) -> 20
A20: Penalised Score /100: | F20: =IF(F18="","",MAX(0,ROUND(F18-F19,1))) -> 39.8
A21: Suggested Grade: | F21: =IF(F20="","",LOOKUP(F20,Ingredients!$A$38:$A$47,Ingredients!$B$38:$B$47)) -> D
A22: Grade Override (optional):
A23: Final Grade: | F23: =IF(F22<>"",F22,IF(F21="","",F21)) -> D
A25: ▼ COOKED FEEDBACK — Select all text below and paste into your feedback system
A26: =IF(F23="","— Select a grade for each criterion above to generate feedback —",VLOOKUP(F23,Pablumator!$A$5:$D$14,3,FALSE())&CHAR(10)&CHAR(10))&IF(G8="","",A8&" – "&TEXT('Student Chart'!D2,"0.0")&" / "&TEXT('Student Chart'!E2,"0")&CHAR(10)&INDEX(Ingredients!$C$4:$I$7,5-G8,1)&CHAR(10)&CHAR(10))&IF(G9="","",A9&" – "&TEXT('Student Chart'!D3,"0.0")&" / "&TEXT('Student Chart'!E3,"0")&CHAR(10)&INDEX(Ingredients!$C$4:$I$7,5-G9,2)&CHAR(10)&CHAR(10))&IF(G10="","",A10&" – "&TEXT('Student Chart'!D4,"0.0")&" / "&TEXT('Student Chart'!E4,"0")&CHAR(10)&INDEX(Ingredients!$C$4:$I$7,5-G10,3)&CHAR(10)&CHAR(10))&IF(G11="","",A11&" – "&TEXT('Student Chart'!D5,"0.0")&" / "&TEXT('Student Chart'!E5,"0")&CHAR(10)&INDEX(Ingredients!$C$4:$I$7,5-G11,4)&CHAR(10)&CHAR(10))&IF(G12="","",A12&" – "&TEXT('Student Chart'!D6,"0.0")&" / "&TEXT('Student Chart'!E6,"0")&CHAR(10)&INDEX(Ingredients!$C$4:$I$7,5-G12,5)&CHAR(10)&CHAR(10))&IF(G13="","",A13&" – "&TEXT('Student Chart'!D7,"0.0")&" / "&TEXT('Student Chart'!E7,"0")&CHAR(10)&INDEX(Ingredients!$C$4:$I$7,5-G13,6)&CHAR(10)&CHAR(10))&IF(G14="","",A14&" – "&TEXT('Student Chart'!D8,"0.0")&" / "&TEXT('Student Chart'!E8,"0")&CHAR(10)&INDEX(Ingredients!$C$4:$I$7,5-G14,7)&CHAR(10)&CHAR(10))&IF(F23<>"",VLOOKUP(F23,Pablumator!$A$5:$D$14,4,FALSE()),"")&CHAR(10)&CHAR(10)&"TOTAL SCORE: "&TEXT('Student Chart'!D9*(1-IFERROR(E19/100,IF(D19="1 day late",0.1,IF(D19="2 days late",0.2,IF(D19="3 days late",0.3,0))))),"0.0")&" / 100"&IF(OR(D19="",D19="On time"),"",CHAR(10)&CHAR(10)&IF(D19="1 day late","LATE SUBMISSION NOTICE: As your report was submitted up to 24 hours / 1 day after the due date/time a further 10% (out of 100%) has been deducted from the total above.",IF(D19="2 days late","LATE SUBMISSION NOTICE: As your report was submitted up to 48 hours / 2 days after the due date/time a further 20% (out of 100%) has been deducted from the total above.","LATE SUBMISSION NOTICE: As your report was submitted up to 72 hours / 3 days after the due date/time a further 30% (out of 100%) has been deducted from the total above."))) -> Thank you for submitting your 5Cs analysis. While I appreciate that you made a submission, the work does not yet meet the expected standard for this assessment. The feedback below outlines the key areas that need significant development, and I would encourage you to engage with this carefully and to seek support if you are unsure how to move forward. New Product Idea – 7.8 / 15 Basic product description with some reference to pain points, but lacking sufficient clarity, newness, or specificity to make a compelling case. Context – PESTLE – 14.2 / 20 Covers most relevant PESTLE factors and links them to the business idea, though some explanations lack depth or supporting references. Company – SWOT – 13.4 / 20 SWOT covers the retailer's strengths, weaknesses, opportunities, and threats clearly, though some elements lack depth or the internal/external distinction could be stronger. Competition – 8.6 / 15 Identifies competitors but does not meaningfully compare them to the new product, or competitive advantages and disadvantages are not clearly explained. Collaborators – 4.4 / 10 No collaborators listed, or collaborators identified lack relevance to the product or the NZ market. Customers – 5.7 / 10 Basic description of customers without meaningful demographic detail, pain point analysis, or NZ-specific focus. Writing & Presentation (incl. APA 7th) – 5.7 / 10 Some grammar or spelling issues, or structure lacks clarity. Subheadings inconsistent or missing. APA referencing attempted but with notable errors. I would strongly encourage you to review the assessment brief and marking rubric carefully, and to make use of the support available to you - whether that is visiting office hours, working with the university's academic skills team, or engaging with the course materials more deeply. Please don't give up - with focused effort and the right support, improvement is absolutely achievable. TOTAL SCORE: 59.8 / 100 LATE SUBMISSION NOTICE: As your report was submitted up to 48 hours / 2 days after the due date/time a further 20% (out of 100%) has been deducted from the total above.
A36: ▼ ADDITIONAL COMMENTS — Add any personalised or summary marking comments and remarks here (this is not pasted onto the student Moodle score unless you choose to do so)
A43: KEY: 🟡 Yellow cells = Tutor input | 🔵 Blue cells = Auto-calculated | Override Score: type a number (e.g. 78) to replace midpoint for that criterion | Late Penalty: select days late from dropdown — score and feedback auto-update | Grade Override: type a grade label (e.g. B+) to replace the calculated final grade
A44: Feedback Kitchen v2.0 | MRKTG101 5Cs Analysis | University of Waikato | Architecture based on original tool by Michael Harker, University of Strathclyde

Sheet Ingredients
A1: MRKTG101 – 5Cs Assessment | Ingredients Sheet | University of Waikato
A2: SECTION 1 — Rubric Descriptors by Tier and Criterion (Extracted from the Student Manual - Lecturer only to change this section)
A3: Tier | B3: Grade Range | C3: New Product Idea | D3: Context – PESTLE | E3: Company – SWOT | F3: Competition | G3: Collaborators | H3: Customers | I3: Writing & Presentation (incl. APA 7th)
A4: Excellent | B4: A+ / A / A- | C4: Concise, well-explained new product idea that directly addresses a current consumer problem. Pain points are clearly identified and supported with relevant evidence or market data. | D4: Comprehensive, focused PESTLE analysis using only relevant macro-environmental factors. All elements are well-explained, linked directly to the business idea, and supported with credible referenced evidence. | E4: Detailed, well-structured SWOT clearly focused on the chosen retailer. Internal S/W grounded in the retailer's capabilities; O/T supported by credible, referenced external evidence. | F4: Clear competitive comparison identifying both direct and indirect competitors. Strengths and weaknesses of the new product vs. existing alternatives are well-evidenced and logically argued. | G4: Well-defined collaborators (suppliers, distributors, promotional partners) with clear roles, a logical distribution strategy, and explanation of each collaborator's importance to success. | H4: Well-defined NZ customer segment with key demographic factors (age, income, lifestyle), clear pain points, and evidence-backed purchasing behaviour linked to the product. | I4: Professionally written, clear, and concise. Well-structured with effective subheadings and formatting. APA 7th in-text citations and reference list correctly applied. Within 3-page limit.
A5: Proficient | B5: B+ / B / B- | C5: Clear new product idea with a solid link to consumer pain points, though some aspects could be more precisely explained or supported with market evidence. | D5: Covers most relevant PESTLE factors and links them to the business idea, though some explanations lack depth or supporting references. | E5: SWOT covers the retailer's strengths, weaknesses, opportunities, and threats clearly, though some elements lack depth or the internal/external distinction could be stronger. | F5: Identifies key competitors and explains basic differences between them and the new product, though the competitive analysis could be more thorough or evidence-based. | G5: Identifies key collaborators and explains their importance, though the distribution strategy or some roles could be more clearly defined or justified. | H5: Defines target customers with at least one relevant demographic factor (e.g., income, age, lifestyle), though depth or NZ-specific evidence could be stronger. | I5: Well-organised with only minor grammar or spelling issues. Subheadings and structure are clear. APA referencing mostly correct with minor errors. Within page limit.
A6: Developing | B6: C+ / C / C- | C6: Basic product description with some reference to pain points, but lacking sufficient clarity, newness, or specificity to make a compelling case. | D6: Some relevant PESTLE factors identified but key ones are missing, or the link to the business idea is unclear or underdeveloped. | E6: SWOT partially completed or lacks depth. May focus on the product rather than the retailer, or internal and external factors are confused or insufficiently evidenced. | F6: Identifies competitors but does not meaningfully compare them to the new product, or competitive advantages and disadvantages are not clearly explained. | G6: Lists some collaborators but lacks detail on their roles, or omits key types such as distributors or promotional partners. | H6: Basic description of customers without meaningful demographic detail, pain point analysis, or NZ-specific focus. | I6: Some grammar or spelling issues, or structure lacks clarity. Subheadings inconsistent or missing. APA referencing attempted but with notable errors.
A7: Unsatisfactory | B7: D | C7: Product idea absent, unclear, or fails to identify meaningful consumer pain points. The proposal lacks a viable foundation. | D7: No macro-environmental analysis, or factors selected are largely irrelevant to the business idea. PESTLE framework not meaningfully applied. | E7: No SWOT analysis, or analysis focuses on the product rather than the chosen retailer. Framework not applied or incorrectly applied. | F7: No competition section, or only a generic list of competitor names with no analysis of how the new product compares. | G7: No collaborators listed, or collaborators identified lack relevance to the product or the NZ market. | H7: No customer section, or audience description is too vague to support any meaningful marketing or targeting decisions. | I7: Poor writing, weak or absent structure, or significantly over the 3-page limit. Little or no attempt at APA referencing.
A8: Criterion Weight (must total 100) | C8: 15 | D8: 20 | E8: 20 | F8: 15 | G8: 10 | H8: 10 | I8: 10
A10: SECTION 2 — Grade → Midpoint Score Mapping (From UWSMM Policy)
A11: Grade | B11: Midpoint Score | C11: Band Notes
A12: A+ | B12: 95 | C12: 90–100 band
A13: A | B13: 87 | C13: 85–89 band
A14: A- | B14: 82 | C14: 80–84 band
A15: B+ | B15: 77 | C15: 75–79 band
A16: B | B16: 72 | C16: 70–74 band
A17: B- | B17: 67 | C17: 65–69 band
A18: C+ | B18: 62 | C18: 60–64 band
A19: C | B19: 57 | C19: 55–59 band
A20: C- | B20: 52 | C20: 50–54 band
A21: D | B21: 44 | C21: 40–49 band — midpoint used
A23: SECTION 3 — Grade → Feedback Tier Mapping
A24: Grade | B24: Feedback Tier | C24: Tier Number (for formulas)
A25: A+ | B25: Excellent | C25: 4
A26: A | B26: Excellent | C26: 4
A27: A- | B27: Excellent | C27: 4
A28: B+ | B28: Proficient | C28: 3
A29: B | B29: Proficient | C29: 3
A30: B- | B30: Proficient | C30: 3
A31: C+ | B31: Developing | C31: 2
A32: C | B32: Developing | C32: 2
A33: C- | B33: Developing | C33: 2
A34: D | B34: Unsatisfactory | C34: 1
A36: SECTION 4 — Grade Threshold Table (used by Kitchen LOOKUP formula)
A37: Score Floor | B37: Grade Label | C37: Notes
A38: 0 | B38: D | C38: Score 40–49 (fail band)
A39: 50 | B39: C- | C39: Score 50–54
A40: 55 | B40: C | C40: Score 55–59
A41: 60 | B41: C+ | C41: Score 60–64
A42: 65 | B42: B- | C42: Score 65–69
A43: 70 | B43: B | C43: Score 70–74
...

Sheet Pablumator
A1: PABLUMATOR | Intro & Outro Text by Grade Tier | Edit cells below to customise your feedback tone
A2: One unique Intro & Outro per grade (A+ through D) | Edit the yellow cells to customise tone for your cohort
A4: Grade | B4: Tier Name | C4: Intro Paragraph | D4: Outro Paragraph
A5: A+ | B5: Excellent A+ | C5: This is genuinely outstanding work. Your 5Cs analysis demonstrates exceptional strategic thinking, a sophisticated command of theory, and the kind of polished, professional writing that sets the benchmark for this assessment. The originality and rigour you've brought to every section are truly impressive. | D5: This is the standard to aspire to. Your analysis is exemplary in its depth, structure, and communication. Continue to challenge yourself and push the boundaries of your thinking. Outstanding effort & you should be very proud of this work.
A6: A | B6: Excellent A | C6: This is excellent work. Your 5Cs analysis is well-structured, analytically strong, and demonstrates a confident grasp of the frameworks and their application. The depth and clarity of your writing reflect a high level of engagement with the material and a real understanding of the strategic context. | D6: Overall, this is an excellent submission that is well-structured, well-argued, and well-written. You should feel confident about the quality of this work. Keep building on these strengths and continue pushing your analysis to the next level. Excellent effort, keep it up!
A7: A- | B7: Excellent A- | C7: This is a very strong piece of work. Your 5Cs analysis shows clear analytical ability and a good command of the relevant frameworks. There are areas of genuine excellence here, and with a little more depth or supporting evidence in places, this could move into the highest band. | D7: This is a very strong submission with several areas of genuine quality. The gap to the top band is narrow, so focus on the specific feedback above to sharpen your analysis and strengthen your evidence base. You're clearly capable of producing top-tier work - keep refining your approach.
A8: B+ | B8: Proficient B+ | C8: Thank you for your 5Cs analysis. This is a solid and well-considered submission that demonstrates a good understanding of the key marketing frameworks. You've engaged meaningfully with the material and there are clear strengths here. With some targeted refinement, you are well-placed to achieve even higher marks. | D8: You've produced a good piece of work with real strengths. To move into the A range, focus on deepening your analysis, supporting claims with stronger evidence, and ensuring consistency across all sections. You're not far off - keep pushing and the next step up is very achievable.
A9: B | B9: Proficient B | C9: Thank you for your 5Cs analysis. This is a competent submission that covers the required frameworks and shows a sound understanding of the core concepts. Your work is generally clear and well-organised, though there are areas where deeper analysis or stronger evidence would lift the quality further. | D9: Overall, this is a competent and well-considered submission. You've shown a good grasp of the 5Cs framework and made a genuine effort throughout. Focus on the areas flagged above to strengthen the depth and rigour of your analysis. Good work - keep pushing forward and you'll continue to improve.
A10: B- | B10: Proficient B- | C10: Thank you for your 5Cs analysis. Your work demonstrates a reasonable understanding of the frameworks, though some sections would benefit from greater depth and more consistent application. The foundations are here, and with more focused analytical effort, there is a clear pathway to stronger results. | D10: The building blocks are here and you're heading in the right direction. Focus on the feedback above - particularly around depth of analysis, use of evidence, and clarity of argument. With some focused effort on these areas, a B or higher is well within your reach next time.
A11: C+ | B11: Developing C+ | C11: Thank you for submitting your 5Cs analysis. Your work shows a developing understanding of the key concepts, with some sections handled better than others. There are promising elements here, and the feedback below is intended to help you see where a little more effort would make a real difference. | D11: There are promising elements in your work, and with more focused effort you can definitely move up. Pay close attention to the feedback above, particularly around analytical depth and use of evidence. I'd encourage you to visit office hours or review the course materials to strengthen your approach for next time.
A12: C | B12: Developing C | C12: Thank you for submitting your 5Cs analysis. Your work shows that you have a basic understanding of the key concepts, and I can see the effort you have put in. There are some foundations here to build on, and the feedback below is intended to help you understand where to focus your energy for future assessments. | D12: There is clear potential in your work, and I encourage you to use this feedback as a roadmap for improvement. Focus on developing deeper analysis, engaging more critically with the theory, and ensuring your writing is clearly structured and supported by evidence. Don't hesitate to reach out if you'd like to discuss any of the feedback — keep working at it, you can do this.
A13: C- | B13: Developing C- | C13: Thank you for submitting your 5Cs analysis. Your work touches on several of the required areas but lacks the depth and consistency needed to demonstrate a secure understanding. I'd encourage you to read the feedback below carefully and use it as a guide for where to focus your efforts going forward. | D13: I know this might not be the result you were hoping for, but please don't be discouraged. Use the feedback above to identify the specific areas to work on, and take advantage of the support available — office hours, the academic skills team, and the course materials. Improvement is very achievable with the right focus.
A14: D | B14: Unsatisfactory | C14: Thank you for submitting your 5Cs analysis. While I appreciate that you made a submission, the work does not yet meet the expected standard for this assessment. The feedback below outlines the key areas that need significant development, and I would encourage you to engage with this carefully and to seek support if you are unsure how to move forward. | D14: I would strongly encourage you to review the assessment brief and marking rubric carefully, and to make use of the support available to you - whether that is visiting office hours, working with the university's academic skills team, or engaging with the course materials more deeply. Please don't give up - with focused effort and the right support, improvement is absolutely achievable.
A16: HOW THE KITCHEN USES THIS SHEET: The Kitchen looks up the student's final grade (A+ through D) directly in column A to pull the matching Intro (col C) and Outro (col D) paragraphs into the Cooked Feedback block. Each grade has its own individually tailored opening and closing tone. Edit the yellow cells above to adjust the wording for your cohort.

Sheet Student Chart
A1: Criterion | B1: Score /100 | C1: Max Marks | D1: Adjusted Score | E1: Maximum | F1: =IF(Kitchen!B5<>"",Kitchen!B5&" — 5C Scores","5C Student Report Profile") -> Mickey Mouse — 5C Scores | G1: Criterion | H1: Adjusted Score | I1: Maximum
A2: =Kitchen!A8 -> New Product Idea | B2: =Kitchen!F8 -> 52 | C2: 15 | D2: =ROUND(B2*C2/100,1) -> 7.8 | E2: =C2 -> 15 | G2: =A2 -> New Product Idea | H2: =D2 -> 7.8 | I2: =E2 -> 15
A3: =Kitchen!A9 -> Context – PESTLE | B3: =Kitchen!F9 -> 71 | C3: 20 | D3: =ROUND(B3*C3/100,1) -> 14.2 | E3: =C3 -> 20 | G3: =A3 -> Context – PESTLE | H3: =D3 -> 14.2 | I3: =E3 -> 20
A4: =Kitchen!A10 -> Company – SWOT | B4: =Kitchen!F10 -> 67 | C4: 20 | D4: =ROUND(B4*C4/100,1) -> 13.4 | E4: =C4 -> 20 | G4: =A4 -> Company – SWOT | H4: =D4 -> 13.4 | I4: =E4 -> 20
A5: =Kitchen!A11 -> Competition | B5: =Kitchen!F11 -> 57 | C5: 15 | D5: =ROUND(B5*C5/100,1) -> 8.6 | E5: =C5 -> 15 | G5: =A5 -> Competition | H5: =D5 -> 8.6 | I5: =E5 -> 15
A6: =Kitchen!A12 -> Collaborators | B6: =Kitchen!F12 -> 44 | C6: 10 | D6: =ROUND(B6*C6/100,1) -> 4.4 | E6: =C6 -> 10 | G6: =A6 -> Collaborators | H6: =D6 -> 4.4 | I6: =E6 -> 10
A7: =Kitchen!A13 -> Customers | B7: =Kitchen!F13 -> 57 | C7: 10 | D7: =ROUND(B7*C7/100,1) -> 5.7 | E7: =C7 -> 10 | G7: =A7 -> Customers | H7: =D7 -> 5.7 | I7: =E7 -> 10
A8: =Kitchen!A14 -> Writing & Presentation (incl. APA 7th) | B8: =Kitchen!F14 -> 57 | C8: 10 | D8: =ROUND(B8*C8/100,1) -> 5.7 | E8: =C8 -> 10 | G8: =A8 -> Writing & Presentation (incl. APA 7th) | H8: =D8 -> 5.7 | I8: =E8 -> 10
A9: TOTAL | C9: =SUM(C2:C8) -> 100 | D9: =SUM(D2:D8) -> 59.8 | E9: =SUM(E2:E8) -> 100

Sheet Demo Stats
A1: DEMO STATS | Time-Savings Calculator | Feedback Kitchen v2.0
A2: Enter values in the yellow cells — all other cells update automatically.
A4: ▼ INPUTS
A5: Cohort size (students) | B5: 56 | C5: Number of students in this cohort
A6: Worst case Ave. time to write all feedback manually (hrs) | B6: =B5*35/60 -> 32.666667 | C6: How many hours for these students without the Kitchen worst case for inexperienced tutors to read and score (ie at best 5mins for ea of the 7 criteria)
A7: Best case Ave. time to write all feedback manually (hrs) | B7: =B5*25/60 -> 23.333333 | C7: How many hours for these students without the Kitchen best case for experienced tutors (ie at best 3.5mins for ea of the 7 criteria)
A8: Worst case Ave. time to use Feedback Kitchen (hrs) | B8: =B5*28/60 -> 26.133333 | C8: Estimated time using the Kitchen tool as a new tutor (ie at best around 4mins per criteria)
A9: Best case Ave. time to use Feedback Kitchen (hrs) | B9: =B5*14/60 -> 13.066667 | C9: Estimated time using the Kitchen tool as an experienced tutor (ie at best around 2mins per criteria)
A11: ▼ TOTAL TIME SAVINGS — CALCULATED FOR THIS COHORT
A12: Total time (manual) — hours | B12: =B6+B7/2 -> 44.333333
A13: Total time (Kitchen) — hours | B13: =B8+B9/2 -> 32.666667
A14: Time saved — hours | B14: =ROUND(B12-B13,1) -> 11.7
A15: Time saved — minutes | B15: =ROUND((B12-B13)*60,0) -> 700
A16: Possible Budget that can be reinvested (x2.5 for all marking in this paper) | B16: =B14*23.5*2.5 -> 687.375
A17: Efficiency gain | B17: =IFERROR(TEXT(1-B8/B6,"0%")&" faster","—") -> 20% faster
A19: NOTE: Estimates and averages only. Actual savings will vary by cohort, assignment complexity, and tutor familiarity with the tool. Feel free to edit the yellow input cells above to reflect your own context or discussions.
